Workbook

Sheet Initial Investment & Cashflows
A2: Project 1:
A3: Beyondfeel Running Shoes 2026
A6: Initial investment
A7: Cost of building:
A8: 210000000
A9: +
A10: Net Working Capital: | K10: Operating cashflow
A11: 0 | K11: 14500000-(14500000*43%_
A12: 0 (R&d sunk cost)
A13: +
A14: 0 interest
A15: Total initial investment= | B15: 210000000
A20: Operating cashflow
A22: Revenue
A24: revune per pair of shoes sold = $198
A25: Net revenue per pair of shoes= $114
A26: Total revenue =pairs sold x total revenue per pair
A27: Net revenue = pairs sold x net revenue per pair
A28: Net adjusted revenue = net revenue - lost sales
A30: Year | B30: Pairs sold | C30: Total revenue per pair | D30: Total revenue | E30: Net revenue per pair | F30: Net revenue | G30: Lost sales | H30: adjusted Revenue
A31: 2026 | B31: 1450000 | C31: 198 | D31: =B31*C31 -> 287100000 | E31: 114 | F31: =B31*E31 -> 165300000 | G31: 22000000 | H31: =F31-G31 -> 143300000
A32: 2027 | B32: 1920000 | C32: 198 | D32: =B32*C32 -> 380160000 | E32: 114 | F32: =B32*E32 -> 218880000 | G32: 12000000 | H32: =F32-G32 -> 206880000
A33: 2028 | B33: 2100000 | C33: 198 | D33: =B33*C33 -> 415800000 | E33: 114 | F33: =B33*E33 -> 239400000 | H33: =F33-G33 -> 239400000
A34: 2029 | B34: 2850000 | C34: 198 | D34: =B34*C34 -> 564300000 | E34: 114 | F34: =B34*E34 -> 324900000 | H34: =F34-G34 -> 324900000
A35: 2030 | B35: 2300000 | C35: 198 | D35: =B35*C35 -> 455400000 | E35: 114 | F35: =B35*E35 -> 262200000 | H35: =F35-G35 -> 262200000
A36: 2031 | B36: 1250000 | C36: 198 | D36: =B36*C36 -> 247500000 | E36: 114 | F36: =B36*E36 -> 142500000 | H36: =F36-G36 -> 142500000
A37: Total | B37: =SUM(B31:B36) -> 11870000 | D37: =SUM(D31:D36) -> 2350260000 | F37: =SUM(F31:F36) -> 1353180000 | G37: =SUM(G31:G32) -> 34000000 | H37: =SUM(H31:H36) -> 1319180000
A40: Varible cost:
A42: variable cost = adjusted revenue x percentage
A43: Varible cost = 43% of net revenue
A45: Year | B45: Net revenue | C45: percentage | D45: Variable cost
A46: 2026 | B46: =B31*E31 -> 165300000 | C46: 0.43 | D46: =B46*C46 -> 71079000
A47: 2027 | B47: =B32*E32 -> 218880000 | C47: 0.43 | D47: =B47*C47 -> 94118400
A48: 2028 | B48: =B33*E33-G33 -> 239400000 | C48: 0.43 | D48: =B48*C48 -> 102942000
A49: 2029 | B49: =B34*E34-G34 -> 324900000 | C49: 0.43 | D49: =B49*C49 -> 139707000
A50: 2030 | B50: =B35*E35-G35 -> 262200000 | C50: 0.43 | D50: =B50*C50 -> 112746000
A51: 2031 | B51: =B36*E36-G36 -> 142500000 | C51: 0.43 | D51: =B51*C51 -> 61275000
A52: Total | B52: =SUM(B46:B51) -> 1353180000 | D52: =SUM(D46:D51) -> 581867400
A55: Fixed cost:
A57: Year | B57: Selling, general and other administrative expenses | C57: Athlete Endorsment | D57: other advertising and promotion cost | E57: Total Fixed cost
...

Sheet Capital budgeting
A1: Project 1:
A2: Running Shoes 2026
A4: Payback Period Method:
A6: Year | B6: Cash Flow | C6: Accumulated Cashflow
A7: 0 | B7: -210000000
A8: 2026 | B8: ='Initial Investment & Cashflows'!B150 -> 18701190 | C8: =C7+B8 -> 18701190
A9: 2027 | B9: ='Initial Investment & Cashflows'!B151 -> 58106664 | C9: =C8+B9 -> 76807854
A10: 2028 | B10: ='Initial Investment & Cashflows'!B152 -> 79854520 | C10: =C9+B10 -> 156662374
A11: 2029 | B11: ='Initial Investment & Cashflows'!B153 -> 110366970 | C11: =C10+B11 -> 267029344
A12: 2030 | B12: ='Initial Investment & Cashflows'!B154 -> 85994960 | C12: =C11+B12 -> 353024304
A13: 2031 | B13: ='Initial Investment & Cashflows'!B155 -> 169272650 | C13: =C12+B13 -> 522296954
A15: Payback period =(210,000,000-156,662,374/110,366,970 +3 years= | B15: =((210000000-C10)/B11)+3 -> 3.4832753
A17: Payback period =3.48 years
A20: The discounted payback:
A21: Discounted payback= | B21: undiscounted cash flow* (1-discount rate)^number of years
A22: Discount Rate= | B22: 0.1
B24: Cash Flow | D24: Accumulated Cash Flow
A25: Year | B25: Undiscounted | C25: Discounted | D25: Undiscounted | E25: Discounted
A26: 2026 | B26: =B8 -> 18701190 | C26: =B26/(1+10%)^1 -> 17001082 | D26: =B26 -> 18701190 | E26: =C26 -> 17001082
A27: 2027 | B27: =B9 -> 58106664 | C27: =B27/(1+10%)^2 -> 48022036 | D27: =D26+B27 -> 76807854 | E27: =E26+C27 -> 65023118
A28: 2028 | B28: =B10 -> 79854520 | C28: =B28/(1+10%)^3 -> 59995883 | D28: =D27+B28 -> 156662374 | E28: =E27+C28 -> 1.25019e+08
A29: 2029 | B29: =B11 -> 110366970 | C29: =B29/(1+10%)^4 -> 75382126 | D29: =D28+B29 -> 267029344 | E29: =E28+C29 -> 2.0040113e+08
A30: 2030 | B30: =B12 -> 85994960 | C30: =B30/(1+10%)^5 -> 53396104 | D30: =D29+B30 -> 353024304 | E30: =E29+C30 -> 2.5379723e+08
A31: 2031 | B31: =B13 -> 169272650 | C31: =B31/(1+10%)^6 -> 95549998 | D31: =D30+B31 -> 522296954 | E31: =E30+C31 -> 3.4934723e+08
A35: Discounted Payback period= | B35: (210,000,000-200,401,126.51)/53,396,104.34 + 4 years
A36: Discounted Payback period= | B36: =((210000000-E29)/C30)+4 -> 4.1797673 | C36: 4.18 Years
A40: Net Present Value (NPV):
A41: Accumulated cashflows = | B41: =E31 -> 3.4934723e+08
A42: initial investment= | B42: 210000000
A44: NPV = Present value of Accumulated cashflows - initial investment= | B44: 349,347,228.85- $210,000,000
A45: NPV = | B45: =E31-B42 -> 1.3934723e+08 | C45: Postive NPV
A48: Profitibility Index:
A49: Accumulated cashflows = | B49: =B41 -> 3.4934723e+08
A50: Initial investment= | B50: =B42 -> 210000000
A51: Profitibility index= Present value of cash flows/ Initial investment | B51: 275,254,943.98/210,000,000
A52: Profitability Index = | B52: =B49/B50 -> 1.6635582
A55: Internal Rate Of Return (IRR):
A56: Initial investment= | B56: =B50 -> 210000000
A57: NPV (0) = -Initial Investment + Present Value of Cashflows /(1+IRR)^n
A58: IRR = | B58: =IRR(B7:B13) -> 0.25124355
...

Sheet WACC
A1: WEIGHTED AVERAGE COST OF CAPITAL
A3: OVERALL COMPANY WACC:
A4: WACC = E/V x Re + D/V x Rd x (1-Tc) | B4: =B8*B10+B9*B14*(1-B17) -> 0.088447619
A5: Firm Value V = Total Equity E + Total Debt D | B5: 21840000000
A6: Total Equity E = | B6: 20080000000
A7: Total Debt D = | B7: 1760000000
A8: Equity weight (E/V) = | B8: =B6/B5 -> 0.91941392
A9: Debt weight (D/V) = | B9: =B7/B5 -> 0.080586081
A10: Cost of Equity Re (CAPM) = Rf + Be x (Rm - Rf) | B10: =B11+B12*(B13) -> 0.0962
A11: Risk Free (Rf) = | B11: 0.0401
A12: Beta (Be) = | B12: 1.02
A13: Market Risk Premium (Rm - Rf) = | B13: 0.055
A14: Cost of Debt Rd = Interst expense/ Total Debt | B14: =B15/B16 -> 0
A15: Interest expense = | B15: 0
A16: Total Debt = | B16: 1760000000
A17: Effective Tax Rate = | B17: 0.305
A21: Project 1 WACC:
A22: WACC = E/V x Re + D/V x Rd x (1-Tc) | B22: =B26*B28+B27*B32*(1-B35) -> 0.10330989
A23: Firm Value (Initial investment) V = Total Equity E + Total Debt D | B23: =B24+B25 -> 210000000
A24: Total Equity E = | B24: =B26*'Initial Investment & Cashflows'!B15 -> 1.9307692e+08
A25: Total Debt D = | B25: =B27*'Initial Investment & Cashflows'!B15 -> 16923077
A26: Equity weight (E/V) = | B26: =B8 -> 0.91941392
A27: Debt weight (D/V) = | B27: =B9 -> 0.080586081
A28: Cost of Equity Re (CAPM) = Rf + Be x (Rm - Rf) | B28: =B29+B30*(B31) -> 0.105
A29: Risk Free (Rf) = | B29: =B11 -> 0.0401
A30: Beta (Be) = | B30: 1.18
A31: Market Risk Premium (Rm - Rf) = | B31: =B13 -> 0.055
A32: Cost of Debt Rd = Interst expense/ Total Debt | B32: =B33/B34 -> 0.10636364
A33: Interest expense = | B33: 1800000
A34: Total Debt = | B34: =B25 -> 16923077
A35: Effective Tax Rate = | B35: 0.21
A39: Project 2 WACC:
A40: WACC = E/V x Re + D/V x Rd x (1-Tc) | B40: =B44*B46+B45*B50*(1-B53) -> 0.11721398
A41: Firm Value (Initial investment) V = Total Equity E + Total Debt D | B41: =B42+B43 -> 90000000
A42: Total Equity E = | B42: =B44*'Initial Investment & Cashflows'!B173 -> 82747253
A43: Total Debt D = | B43: =B45*'Initial Investment & Cashflows'!B173 -> 7252747.3
A44: Equity weight (E/V) = | B44: =B8 -> 0.91941392
A45: Debt weight (D/V) = | B45: =B9 -> 0.080586081
A46: Cost of Equity Re (CAPM) = Rf + Be x (Rm - Rf) | B46: =B47+B48*(B49) -> 0.11985
A47: Risk Free (Rf) = | B47: =B11 -> 0.0401
...

Sheet ANPV
A1: Project 1: Beyonfeel Running Shoes 2026
A3: NPV = | B3: ='Capital budgeting'!B45 -> 1.3934723e+08 | D3: Year | E3: CashFlows | F3: Discounted CashFlows
A4: Number of Years (n) = | B4: 6 | D4: 0 | E4: -210000000
A5: Discount Rate = | B5: 0.1 | D5: 2026 | E5: ='Capital budgeting'!B8 -> 18701190 | F5: ='Capital budgeting'!C26 -> 17001082
A6: PVIFA = | B6: 4.355 | D6: 2027 | E6: ='Capital budgeting'!B9 -> 58106664 | F6: ='Capital budgeting'!C27 -> 48022036
D7: 2028 | E7: ='Capital budgeting'!B10 -> 79854520 | F7: ='Capital budgeting'!C28 -> 59995883
A8: ANPV = NPV/PVIFA | B8: 139,347,228.85/4.355 | D8: 2029 | E8: ='Capital budgeting'!B11 -> 110366970 | F8: ='Capital budgeting'!C29 -> 75382126
A9: ANPV = | B9: =B3/B6 -> 31997067 | D9: 2030 | E9: ='Capital budgeting'!B12 -> 85994960 | F9: ='Capital budgeting'!C30 -> 53396104
D10: 2031 | E10: ='Capital budgeting'!B13 -> 169272650 | F10: ='Capital budgeting'!C31 -> 95549998
A14: Project 2: Trail & Travel
A16: NPV = | B16: ='Capital budgeting'!B103 -> -9929.6003 | D16: Year | E16: CashFlows | F16: Discounted CashFlows
A17: Number of Years (n) = | B17: 3 | D17: 0 | E17: -90000000
A18: Discount Rate = | B18: 0.12 | D18: 2026 | E18: ='Capital budgeting'!B90 -> 19708150 | F18: ='Capital budgeting'!C90 -> 17596562
A19: PVIFA = | B19: 2.402 | D19: 2027 | E19: ='Capital budgeting'!B91 -> 32251761 | F19: ='Capital budgeting'!C91 -> 25710906
D20: 2028 | E20: ='Capital budgeting'!B92 -> 65585695 | F20: ='Capital budgeting'!C92 -> 46682602
A21: ANPV = NPV/PVIFA | B21: -9,929.60/2.402
A22: ANPV = | B22: =B16/B19 -> -4133.8885

Sheet sensitivity analysis
A1: Project 1:
A2: Beyondfeel Running Shoes 2026
A4: Year | B4: Cashflow
A5: 0 | B5: -210000000
A6: 2026 | B6: ='Initial Investment & Cashflows'!B150 -> 18701190
A7: 2027 | B7: ='Initial Investment & Cashflows'!B151 -> 58106664
A8: 2028 | B8: ='Initial Investment & Cashflows'!B152 -> 79854520
A9: 2029 | B9: ='Initial Investment & Cashflows'!B153 -> 110366970
A10: 2030 | B10: ='Initial Investment & Cashflows'!B154 -> 85994960
A11: 2031 | B11: ='Initial Investment & Cashflows'!B155 -> 169272650
A17: Discount Rate | B17: PV of Cash Flows | C17: NPV
A18: 0.0884 | B18: =NPV(A18,B6:B11) -> 3.649437e+08 | C18: =B5+B18 -> 1.549437e+08 | D18: WACC
A19: 0.1 | B19: =NPV(A19,B6:B11) -> 3.4934723e+08 | C19: =B5+B19 -> 1.3934723e+08 | D19: Given rate
A20: 0.11 | B20: =NPV(A20,B6:B11) -> 3.3663356e+08 | C20: =B5+B20 -> 1.2663356e+08
A21: 0.12 | B21: =NPV(A21,B6:B11) -> 3.2455348e+08 | C21: =B5+B21 -> 1.1455348e+08
A27: Project 2:
A28: Trail & Travel 2026
A30: Year | B30: Cash Flow
A31: 0 | B31: -90000000
A32: 2026 | B32: ='Initial Investment & Cashflows'!B293 -> 19708150
A33: 2027 | B33: ='Initial Investment & Cashflows'!B294 -> 32251761
A34: 2028 | B34: ='Initial Investment & Cashflows'!B295 -> 65585695
A39: Discount Rate | B39: PV of Cash Flows | C39: NPV
A40: 0.0884 | B40: =NPV(A40,B32:B34) -> 96200849 | C40: =B31+B40 -> 6200848.8 | D40: wacc
A41: 0.1 | B41: =NPV(A41,B32:B34) -> 93846351 | C41: =B31+B41 -> 3846350.5
A42: 0.11 | B42: =NPV(A42,B32:B34) -> 91887037 | C42: =B31+B42 -> 1887037
A43: 0.12 | B43: =NPV(A43,B32:B34) -> 89990070 | C43: =B31+B43 -> -9929.6003 | D43: Given rate
