Workbook

Sheet Business Line By Segm
A1: Company Fundamentals - Segments
A2: Company Name | B2: Lululemon Athletica Inc (LULU.O)
A3: Country of Exchange | B3: United States of America
A4: Country of Headquarters | B4: Canada
A5: TRBC Industry Group | B5: Textiles & Apparel
A6: CF Template | B6: IND
A7: Consolidation Basis | B7: Consolidated
A8: Scaling | B8: Millions
A9: Period | B9: Annual
A10: Export Date | B10: 45922.395
A11: Statement Data | C11: 2025 | D11: 2024 | E11: 2023 | F11: 2022 | G11: 2021 | H11: 2020 | I11: 2019
A12: Period End Date | C12: 45690 | D12: 45319 | E12: 44955 | F12: 44591 | G12: 44227 | H12: 43863 | I12: 43499
A13: Statement Date | C13: 45690 | D13: 45319 | E13: 45319 | F13: 45319 | G13: 44227 | H13: 43863 | I13: 43499
A14: Standardized Currency | C14: USD | D14: USD | E14: USD | F14: USD | G14: USD | H14: USD | I14: USD
A15: Template Type | C15: Industrial | D15: Industrial | E15: Industrial | F15: Industrial | G15: Industrial | H15: Industrial | I15: Industrial
A17: Segments - Business Line By Segment (Currency: Standardized)
A18: Field Name | B18: TRBC | C18: 02-02-2025 | D18: 28-01-2024 | E18: 29-01-2023 | F18: 30-01-2022 | G18: 31-01-2021 | H18: 02-02-2020 | I18: 03-02-2019
A19: Company-operated stores | B19: 458110
A20: Depreciation & Amortization | G20: 100.78 | H20: 97.9 | I20: 76.3
A21: External Revenue | G21: 1658.81 | H21: 2501.07 | I21: 2126.36
A22: Fixed Assets - Purchased - Cash Flow | G22: 134.2 | H22: 171.5 | I22: 129.16
A23: Operating Income/Loss | G23: 212.59 | H23: 689.34 | I23: 575.54
A24: Direct To Consumers | B24: 315990, 315250
A25: Depreciation & Amortization | G25: 14.85 | H25: 12.47 | I25: 10.02
A26: External Revenue | G26: 2284.07 | H26: 1137.82 | I26: 858.86
A27: Fixed Assets - Purchased - Cash Flow | G27: 37.24 | H27: 15.81 | I27: 6.42
A28: Operating Income/Loss | G28: 1029.1 | H28: 482.37 | I28: 354.11
A29: Corporate & Other
A30: Amortization of Intangibles excluding Goodwill | C30: 2.74
A31: Depreciation & Amortization | C31: 177.52 | D31: 159.58 | E31: 117.34 | F31: 73.89 | G31: 69.86 | H31: 51.57 | I31: 36.16
A32: Fixed Assets - Purchased - Cash Flow | G32: 57.78 | H32: 95.74 | I32: 90.23
A33: Operating Income/Loss | C33: -1334.66 | D33: -1343.66 | E33: -1477.4 | F33: -768.65 | G33: -432.21 | H33: -355.16 | I33: -286.36
A34: Americas | B34: 315990, 315210, 458110
A35: Depreciation & Amortization | C35: 204.92 | D35: 170.42 | E35: 137.26 | F35: 121.28
A36: External Revenue | C36: 7928.16 | D36: 7631.65 | E36: 6817.45 | F36: 5299.91
A37: Operating Income/Loss | C37: 3015.56 | D37: 2937.18 | E37: 2503.74 | F37: 1867.02
A38: China Mainland | B38: 315990, 315210, 458110
A39: Depreciation & Amortization | C39: 33.21 | D39: 25.75 | E39: 17.84 | F39: 12.21
A40: External Revenue | C40: 1361.34 | D40: 963.76 | E40: 576.5 | F40: 434.26
A41: Operating Income/Loss | C41: 509.86 | D41: 337.32 | E41: 196.87 | F41: 167.32
...

Sheet Business Line By Stat
A1: Company Fundamentals - Segments
A2: Company Name | B2: Lululemon Athletica Inc (LULU.O)
A3: Country of Exchange | B3: United States of America
A4: Country of Headquarters | B4: Canada
A5: TRBC Industry Group | B5: Textiles & Apparel
A6: CF Template | B6: IND
A7: Consolidation Basis | B7: Consolidated
A8: Scaling | B8: Millions
A9: Period | B9: Annual
A10: Export Date | B10: 45922.395
A11: Statement Data | C11: 2025 | D11: 2024 | E11: 2023 | F11: 2022 | G11: 2021 | H11: 2020 | I11: 2019
A12: Period End Date | C12: 45690 | D12: 45319 | E12: 44955 | F12: 44591 | G12: 44227 | H12: 43863 | I12: 43499
A13: Statement Date | C13: 45690 | D13: 45319 | E13: 44955 | F13: 44591 | G13: 44227 | H13: 43863 | I13: 43499
A14: Standardized Currency | C14: USD | D14: USD | E14: USD | F14: USD | G14: USD | H14: USD | I14: USD
A15: Template Type | C15: Industrial - Gross Profit | D15: Industrial - Gross Profit | E15: Industrial - Gross Profit | F15: Industrial - Gross Profit | G15: Industrial - Gross Profit | H15: Industrial - Gross Profit | I15: Industrial - Gross Profit
A17: Segments - Business Line By Statement Item (Currency: Standardized)
A18: Field Name | B18: TRBC | C18: 02-02-2025 | D18: 28-01-2024 | E18: 29-01-2023 | F18: 30-01-2022 | G18: 31-01-2021 | H18: 02-02-2020 | I18: 03-02-2019
A19: Fixed Assets - Purchased - Cash Flow | G19: 229.23 | H19: 283.05 | I19: 225.81
A20: Company-operated stores | B20: 458110 | G20: 134.2 | H20: 171.5 | I20: 129.16
A21: Corporate & Other | G21: 57.78 | H21: 95.74 | I21: 90.23
A22: Direct To Consumers | B22: 315990, 315250 | G22: 37.24 | H22: 15.81 | I22: 6.42
A23: Operating Income/Loss | C23: 2505.7 | D23: 2132.68 | E23: 1328.41 | F23: 1333.36 | G23: 819.99 | H23: 889.11 | I23: 705.84
A24: Americas | B24: 315990, 315210, 458110 | C24: 3015.56 | D24: 2937.18 | E24: 2503.74 | F24: 1867.02
A25: China Mainland | B25: 315990, 315210, 458110 | C25: 509.86 | D25: 337.32 | E25: 196.87 | F25: 167.32
A26: Company-operated stores | B26: 458110 | G26: 212.59 | H26: 689.34 | I26: 575.54
A27: Corporate & Other | C27: -1334.66 | D27: -1343.66 | E27: -1477.4 | F27: -768.65 | G27: -432.21 | H27: -355.16 | I27: -286.36
A28: Direct To Consumers | B28: 315990, 315250 | G28: 1029.1 | H28: 482.37 | I28: 354.11
A29: Other | G29: 10.5 | H29: 72.56 | I29: 62.56
A30: Rest of World | B30: 315990, 315210, 458110 | C30: 314.95 | D30: 201.83 | E30: 103.2 | F30: 67.67
A31: External Revenue | C31: 10588.13 | D31: 9619.28 | E31: 8110.52 | F31: 6256.62 | G31: 4401.88 | H31: 3979.3 | I31: 3288.32
A32: Americas | B32: 315990, 315210, 458110 | C32: 7928.16 | D32: 7631.65 | E32: 6817.45 | F32: 5299.91
A33: China Mainland | B33: 315990, 315210, 458110 | C33: 1361.34 | D33: 963.76 | E33: 576.5 | F33: 434.26
A34: Company-operated stores | B34: 458110 | G34: 1658.81 | H34: 2501.07 | I34: 2126.36
A35: Direct To Consumers | B35: 315990, 315250 | G35: 2284.07 | H35: 1137.82 | I35: 858.86
A36: Other | G36: 459 | H36: 340.41 | I36: 303.1
A37: Rest of World | B37: 315990, 315210, 458110 | C37: 1298.63 | D37: 1023.87 | E37: 716.56 | F37: 522.45
A38: Depreciation & Amortization | C38: 446.52 | D38: 379.38 | E38: 291.79 | F38: 224.21 | G38: 185.48 | H38: 161.93 | I38: 122.48
A39: Americas | B39: 315990, 315210, 458110 | C39: 204.92 | D39: 170.42 | E39: 137.26 | F39: 121.28
A40: China Mainland | B40: 315990, 315210, 458110 | C40: 33.21 | D40: 25.75 | E40: 17.84 | F40: 12.21
A41: Company-operated stores | B41: 458110 | G41: 100.78 | H41: 97.9 | I41: 76.3
...

Sheet Geographic Line By Se
A1: Company Fundamentals - Segments
A2: Company Name | B2: Lululemon Athletica Inc (LULU.O)
A3: Country of Exchange | B3: United States of America
A4: Country of Headquarters | B4: Canada
A5: TRBC Industry Group | B5: Textiles & Apparel
A6: CF Template | B6: IND
A7: Consolidation Basis | B7: Consolidated
A8: Scaling | B8: Millions
A9: Period | B9: Annual
A10: Export Date | B10: 45922.395
A11: Statement Data | B11: 2025 | C11: 2024 | D11: 2023 | E11: 2022 | F11: 2021 | G11: 2020 | H11: 2019
A12: Period End Date | B12: 45690 | C12: 45319 | D12: 44955 | E12: 44591 | F12: 44227 | G12: 43863 | H12: 43499
A13: Statement Date | B13: 45690 | C13: 45319 | D13: 44955 | E13: 44591 | F13: 44227 | G13: 43863 | H13: 43499
A14: Standardized Currency | B14: USD | C14: USD | D14: USD | E14: USD | F14: USD | G14: USD | H14: USD
A15: Template Type | B15: Industrial | C15: Industrial | D15: Industrial | E15: Industrial | F15: Industrial | G15: Industrial | H15: Industrial
A17: Segments - Geographic Line By Segment (Currency: Standardized)
A18: Field Name | B18: 02-02-2025 | C18: 28-01-2024 | D18: 29-01-2023 | E18: 30-01-2022 | F18: 31-01-2021 | G18: 02-02-2020 | H18: 03-02-2019
A19: United States
A20: Employees - Full-Time/Full-Time Equivalents - Period End | G20: 11000 | H20: 9200
A21: External Revenue | B21: 6483.18 | C21: 6346.39 | D21: 5654.34 | E21: 4345.69 | F21: 3105.13 | G21: 2854.36 | H21: 2363.37
A22: Long-lived Assets | B22: 1788.55 | C22: 1597.32
A23: Net Income before Tax | B23: 479.96 | C23: 458.04 | D23: -98.76 | E23: 204.35 | F23: 122.57 | G23: 180.04 | H23: 132.56
A24: Property, Plant & Equipment - Net - Total | D24: 671.21 | E24: 418.32 | F24: 267.33 | G24: 259.49 | H24: 217.87
A25: Canada
A26: Employees - Full-Time/Full-Time Equivalents - Period End | G26: 5200 | H26: 4200
A27: External Revenue | B27: 1411.67 | C27: 1285.26 | D27: 1163.11 | E27: 954.22 | F27: 672.61 | G27: 649.11 | H27: 565.11
A28: Long-lived Assets | B28: 675.05 | C28: 671.62
A29: Property, Plant & Equipment - Net - Total | D29: 431.35 | E29: 392.19 | F29: 394.86 | G29: 346.31 | H29: 303.06
A30: Outside of the North America
A31: Employees - Full-Time/Full-Time Equivalents - Period End | G31: 2800 | H31: 2200
A32: External Revenue | C32: 853.34 | D32: 611.43 | E32: 956.71 | F32: 624.14 | G32: 475.82 | H32: 359.84
A33: Long-lived Assets | C33: 257.91
A34: Property, Plant & Equipment - Net - Total | D34: 167.05 | E34: 117.2 | F34: 83.5 | G34: 65.9 | H34: 46.3
A35: People's Republic of China
A36: External Revenue | B36: 1541.43 | C36: 1134.29 | D36: 681.63
A37: Long-lived Assets | B37: 326.62 | C37: 284.58
A38: Other geographic areas
A39: External Revenue | B39: 1118.54
A40: Long-lived Assets | B40: 406.65
A41: Mexico
...

Sheet Geographic Line By St
A1: Company Fundamentals - Segments
A2: Company Name | B2: Lululemon Athletica Inc (LULU.O)
A3: Country of Exchange | B3: United States of America
A4: Country of Headquarters | B4: Canada
A5: TRBC Industry Group | B5: Textiles & Apparel
A6: CF Template | B6: IND
A7: Consolidation Basis | B7: Consolidated
A8: Scaling | B8: Millions
A9: Period | B9: Annual
A10: Export Date | B10: 45922.395
A11: Statement Data | B11: 2025 | C11: 2024 | D11: 2023 | E11: 2022 | F11: 2021 | G11: 2020 | H11: 2019
A12: Period End Date | B12: 45690 | C12: 45319 | D12: 44955 | E12: 44591 | F12: 44227 | G12: 43863 | H12: 43499
A13: Statement Date | B13: 45690 | C13: 45319 | D13: 44955 | E13: 44591 | F13: 44227 | G13: 43863 | H13: 43499
A14: Standardized Currency | B14: USD | C14: USD | D14: USD | E14: USD | F14: USD | G14: USD | H14: USD
A15: Template Type | B15: Industrial - Gross Profit | C15: Industrial - Gross Profit | D15: Industrial - Gross Profit | E15: Industrial - Gross Profit | F15: Industrial - Gross Profit | G15: Industrial - Gross Profit | H15: Industrial - Gross Profit
A17: Segments - Geographic Line By Statement Item (Currency: Standardized)
A18: Field Name | B18: 02-02-2025 | C18: 28-01-2024 | D18: 29-01-2023 | E18: 30-01-2022 | F18: 31-01-2021 | G18: 02-02-2020 | H18: 03-02-2019
A19: Employees - Full-Time/Full-Time Equivalents - Period End | G19: 19000 | H19: 15600
A20: Canada | G20: 5200 | H20: 4200
A21: Outside of the North America | G21: 2800 | H21: 2200
A22: United States | G22: 11000 | H22: 9200
A23: External Revenue | B23: 10588.13 | C23: 9619.28 | D23: 8110.52 | E23: 6256.62 | F23: 4401.88 | G23: 3979.3 | H23: 3288.32
A24: Canada | B24: 1411.67 | C24: 1285.26 | D24: 1163.11 | E24: 954.22 | F24: 672.61 | G24: 649.11 | H24: 565.11
A25: Mexico | B25: 33.3
A26: Other geographic areas | B26: 1118.54
A27: Outside of the North America | C27: 853.34 | D27: 611.43 | E27: 956.71 | F27: 624.14 | G27: 475.82 | H27: 359.84
A28: People's Republic of China | B28: 1541.43 | C28: 1134.29 | D28: 681.63
A29: United States | B29: 6483.18 | C29: 6346.39 | D29: 5654.34 | E29: 4345.69 | F29: 3105.13 | G29: 2854.36 | H29: 2363.37
A30: International Assets | B30: 2521.82 | C30: 2139.8
A31: International Sales | B31: 9176.45 | C31: 8334.02 | D31: 6947.41 | E31: 5302.4 | F31: 3729.27 | G31: 3330.18 | H31: 2723.21
A32: Property, Plant & Equipment - Net - Total | D32: 1269.61 | E32: 927.71 | F32: 745.69 | G32: 671.69 | H32: 567.24
A33: Canada | D33: 431.35 | E33: 392.19 | F33: 394.86 | G33: 346.31 | H33: 303.06
A34: Outside of the North America | D34: 167.05 | E34: 117.2 | F34: 83.5 | G34: 65.9 | H34: 46.3
A35: United States | D35: 671.21 | E35: 418.32 | F35: 267.33 | G35: 259.49 | H35: 217.87
A36: Net Income before Tax | B36: 2576.08 | C36: 2175.74 | D36: 1332.57 | E36: 1333.87 | F36: 819.35 | G36: 897.39 | H36: 715.25
A37: Foreign | B37: 2096.12 | C37: 1717.69 | D37: 1431.34 | E37: 1129.52 | F37: 696.78 | G37: 717.35 | H37: 582.69
A38: United States | B38: 479.96 | C38: 458.04 | D38: -98.76 | E38: 204.35 | F38: 122.57 | G38: 180.04 | H38: 132.56
A39: Long-lived Assets | B39: 3196.87 | C39: 2811.42
A40: Canada | B40: 675.05 | C40: 671.62
A41: Other geographic areas | B41: 406.65
...

Sheet Product Line By Segme
A1: Company Fundamentals - Segments
A2: Company Name | B2: Lululemon Athletica Inc (LULU.O)
A3: Country of Exchange | B3: United States of America
A4: Country of Headquarters | B4: Canada
A5: TRBC Industry Group | B5: Textiles & Apparel
A6: CF Template | B6: IND
A7: Consolidation Basis | B7: Consolidated
A8: Scaling | B8: Millions
A9: Period | B9: Annual
A10: Export Date | B10: 45922.395
A11: Statement Data | B11: 2025 | C11: 2024 | D11: 2023 | E11: 2022 | F11: 2021 | G11: 2020
A12: Period End Date | B12: 45690 | C12: 45319 | D12: 44955 | E12: 44591 | F12: 44227 | G12: 43863
A13: Statement Date | B13: 45690 | C13: 45319 | D13: 44955 | E13: 44591 | F13: 44227 | G13: 43863
A14: Standardized Currency | B14: USD | C14: USD | D14: USD | E14: USD | F14: USD | G14: USD
A15: Template Type | B15: Industrial | C15: Industrial | D15: Industrial | E15: Industrial | F15: Industrial | G15: Industrial
A17: Segments - Product Line By Segment (Currency: Standardized)
A18: Field Name | B18: 02-02-2025 | C18: 28-01-2024 | D18: 29-01-2023 | E18: 30-01-2022 | F18: 31-01-2021 | G18: 02-02-2020
A19: Womens Product-Mens Product
A20: External Revenue | B20: 2558.38 | C20: 2252.75 | D20: 1956.6 | E20: 1535.85 | F20: 953.18 | G20: 933.77
A21: Mens Product-Womens Product
A22: External Revenue | B22: 6692.63 | C22: 6147.37 | D22: 5259.8 | E22: 4171.76 | F22: 3049.91 | G22: 2791
A23: Other Categories
A24: External Revenue | B24: 1337.12 | C24: 1219.15 | D24: 894.11 | E24: 549.01 | F24: 398.79 | G24: 254.53
A25: Total
A26: External Revenue | B26: 10588.13 | C26: 9619.28 | D26: 8110.52 | E26: 6256.62 | F26: 4401.88 | G26: 3979.3

Sheet Product Line By State
A1: Company Fundamentals - Segments
A2: Company Name | B2: Lululemon Athletica Inc (LULU.O)
A3: Country of Exchange | B3: United States of America
A4: Country of Headquarters | B4: Canada
A5: TRBC Industry Group | B5: Textiles & Apparel
A6: CF Template | B6: IND
A7: Consolidation Basis | B7: Consolidated
A8: Scaling | B8: Millions
A9: Period | B9: Annual
A10: Export Date | B10: 45922.395
A11: Statement Data | B11: 2025 | C11: 2024 | D11: 2023 | E11: 2022 | F11: 2021 | G11: 2020
A12: Period End Date | B12: 45690 | C12: 45319 | D12: 44955 | E12: 44591 | F12: 44227 | G12: 43863
A13: Statement Date | B13: 45690 | C13: 45319 | D13: 44955 | E13: 44591 | F13: 44227 | G13: 43863
A14: Standardized Currency | B14: USD | C14: USD | D14: USD | E14: USD | F14: USD | G14: USD
A15: Template Type | B15: Industrial | C15: Industrial | D15: Industrial | E15: Industrial | F15: Industrial | G15: Industrial
A17: Segments - Product Line By Statement Item (Currency: Standardized)
A18: Field Name | B18: 02-02-2025 | C18: 28-01-2024 | D18: 29-01-2023 | E18: 30-01-2022 | F18: 31-01-2021 | G18: 02-02-2020
A19: External Revenue | B19: 10588.13 | C19: 9619.28 | D19: 8110.52 | E19: 6256.62 | F19: 4401.88 | G19: 3979.3
A20: Mens Product-Womens Product | B20: 6692.63 | C20: 6147.37 | D20: 5259.8 | E20: 4171.76 | F20: 3049.91 | G20: 2791
A21: Other Categories | B21: 1337.12 | C21: 1219.15 | D21: 894.11 | E21: 549.01 | F21: 398.79 | G21: 254.53
A22: Womens Product-Mens Product | B22: 2558.38 | C22: 2252.75 | D22: 1956.6 | E22: 1535.85 | F22: 953.18 | G22: 933.77

Sheet Income Statement
A1: Company Fundamentals - Income Statement
A2: Company Name | B2: Lululemon Athletica Inc (LULU.O)
A3: Country of Exchange | B3: United States of America
A4: Country of Headquarters | B4: Canada
A5: TRBC Industry Group | B5: Textiles & Apparel
A6: CF Template | B6: IND
A7: Consolidation Basis | B7: Consolidated
A8: Scaling | B8: Millions
A9: Period | B9: Annual
A10: Export Date | B10: 45922.395
A11: Statement Data | B11: 2025 | C11: 2024 | D11: 2023 | E11: 2022 | F11: 2021 | G11: 2020 | H11: 2019
A12: Period End Date | B12: 45690 | C12: 45319 | D12: 44955 | E12: 44591 | F12: 44227 | G12: 43863 | H12: 43499
A13: Statement Date | B13: 45690 | C13: 45319 | D13: 44955 | E13: 44591 | F13: 44227 | G13: 43863 | H13: 43499
A14: Standardized Currency | B14: USD | C14: USD | D14: USD | E14: USD | F14: USD | G14: USD | H14: USD
A15: Template Type | B15: Industrial - Gross Profit | C15: Industrial - Gross Profit | D15: Industrial - Gross Profit | E15: Industrial - Gross Profit | F15: Industrial - Gross Profit | G15: Industrial - Gross Profit | H15: Industrial - Gross Profit
A17: Income Statement - Standardized (Currency: Standardized)
A18: Field Name | B18: 02-02-2025 | C18: 28-01-2024 | D18: 29-01-2023 | E18: 30-01-2022 | F18: 31-01-2021 | G18: 02-02-2020 | H18: 03-02-2019
A19: Revenues
A20: Revenue from Goods & Services | B20: 10588.13 | C20: 9619.28 | D20: 8110.52 | E20: 6256.62 | F20: 4401.88 | G20: 3979.3 | H20: 3288.32
A21: Sales of Goods & Services - Net - Unclassified | B21: 10588.13 | C21: 9619.28 | D21: 8110.52 | E21: 6256.62 | F21: 4401.88 | G21: 3979.3 | H21: 3288.32
A22: Revenue from Business Activities - Total | B22: 10588.13 | C22: 9619.28 | D22: 8110.52 | E22: 6256.62 | F22: 4401.88 | G22: 3979.3 | H22: 3288.32
A23: Operating Expenses
A24: Cost of Operating Revenue | B24: 4320.05 | C24: 4014.88 | D24: 3626.93 | E24: 2656.83 | F24: 1943.05 | G24: 1755.91 | H24: 1472.03
A25: Cost of Revenues - Total | B25: 4320.05 | C25: 4014.88 | D25: 3626.93 | E25: 2656.83 | F25: 1943.05 | G25: 1755.91 | H25: 1472.03
A26: Cost of Revenues - Unclassified | B26: 4317.31 | C26: 4009.87 | D26: 3618.18 | E26: 2648.05 | F26: 1937.89
A27: Amortization in Cost of Revenues | B27: 2.74 | C27: 5.01 | D27: 8.75 | E27: 8.78 | F27: 5.16
A28: Gross Profit - Industrials/Property - Total | B28: 6268.08 | C28: 5604.4 | D28: 4483.59 | E28: 3599.78 | F28: 2458.83 | G28: 2223.39 | H28: 1816.29
A29: Selling, General & Administrative Expenses - Total | B29: 3758.88 | C29: 3397.22 | D29: 2757.45 | E29: 2225.03 | F29: 1609 | G29: 1332.77 | H29: 1111.84
A30: Selling, General & Administrative Expenses - Unclassified | B30: 3217.38
A31: Selling, General & Administrative Expenses - Other - Total | B31: 541.5
A32: Advertising Expense | B32: 541.5
A33: Operating Expenses - Total | B33: 8078.93 | C33: 7412.1 | D33: 6384.38 | E33: 4881.87 | F33: 3552.05 | G33: 3088.68 | H33: 2583.88
A34: Operating Profit
A35: Operating Profit before Non-Recurring Income/Expense | B35: 2509.2 | C35: 2207.18 | D35: 1726.14 | E35: 1374.75 | F35: 849.83 | G35: 890.62 | H35: 704.44
A36: Non-Operating Expenses
A37: Financing Income/(Expense) - Net - Total
A38: Interest Expense - Net of (Interest Income) | D38: -67.9 | E38: -35.8 | F38: -23.5 | G38: -0.02 | H38: -0.01
A39: Interest Expense - Net of Capitalized Interest | D39: -67.9 | E39: -35.8 | F39: -23.5 | G39: -0.02 | H39: -0.01
A40: Interest Capitalized | D40: 67.9 | E40: 35.8 | F40: 23.5 | G40: 0.02 | H40: 0.01
A41: Non-Interest Financial Income/(Expense) - Total | D41: -67.9 | E41: -35.8 | F41: -23.5 | G41: -0.02 | H41: -0.01
...

Sheet Balance Sheet
A1: Company Fundamentals - Balance Sheet
A2: Company Name | B2: Lululemon Athletica Inc (LULU.O)
A3: Country of Exchange | B3: United States of America
A4: Country of Headquarters | B4: Canada
A5: TRBC Industry Group | B5: Textiles & Apparel
A6: CF Template | B6: IND
A7: Consolidation Basis | B7: Consolidated
A8: Scaling | B8: Millions
A9: Period | B9: Annual
A10: Export Date | B10: 45922.395
A11: Statement Data | B11: 2025 | C11: 2024 | D11: 2023 | E11: 2022 | F11: 2021 | G11: 2020 | H11: 2019
A12: Period End Date | B12: 45690 | C12: 45319 | D12: 44955 | E12: 44591 | F12: 44227 | G12: 43863 | H12: 43499
A13: Statement Date | B13: 45690 | C13: 45319 | D13: 44955 | E13: 44591 | F13: 44227 | G13: 43863 | H13: 43499
A14: Standardized Currency | B14: USD | C14: USD | D14: USD | E14: USD | F14: USD | G14: USD | H14: USD
A15: Template Type | B15: Industrial - Differentiated | C15: Industrial - Differentiated | D15: Industrial - Differentiated | E15: Industrial - Differentiated | F15: Industrial - Differentiated | G15: Industrial - Differentiated | H15: Industrial - Differentiated
A17: Balance Sheet - Standardized (Currency: Standardized)
A18: Field Name | B18: 02-02-2025 | C18: 28-01-2024 | D18: 29-01-2023 | E18: 30-01-2022 | F18: 31-01-2021 | G18: 02-02-2020 | H18: 03-02-2019
A19: Current Assets
A20: Cash & Short-Term Investments | B20: 1984.34 | C20: 2243.97 | D20: 1154.87 | E20: 1259.87 | F20: 1150.52 | G20: 1093.51 | H20: 881.32
A21: Cash & Cash Equivalents | B21: 1984.34 | C21: 2243.97 | D21: 1154.87 | E21: 1259.87 | F21: 1150.52 | G21: 1093.51 | H21: 881.32
A22: Derivative Financial Instruments - Hedging - Short-Term | B22: 76.85 | C22: 0.65 | D22: 16.71 | E22: 19.08 | F22: 17.36 | G22: 0.15 | H22: 0.52
A23: Loans & Receivables - Net - Short-Term | B23: 120.17 | C23: 124.77 | D23: 132.91 | E23: 77 | F23: 75.71 | G23: 40.22 | H23: 35.79
A24: Trade Accounts & Trade Notes Receivable - Net | B24: 120.17 | C24: 124.77 | D24: 132.91 | E24: 77 | F24: 62.4 | G24: 40.22 | H24: 35.79
A25: Receivables - Other - Total | F25: 13.31
A26: Inventories - Total | B26: 1442.08 | C26: 1323.6 | D26: 1447.37 | E26: 966.48 | F26: 647.23 | G26: 518.51 | H26: 404.84
A27: Inventories - Finished Goods | B27: 1526.06 | C27: 1465.08 | D27: 1571.98 | E27: 1004.53 | F27: 678.2 | G27: 540.58 | H27: 420.93
A28: Inventories - Other - Total | B28: -83.97 | C28: -141.47 | D28: -124.61 | E28: -38.04 | F28: -30.97 | G28: -22.07 | H28: -16.09
A29: Prepaid Expenses - Short-Term | B29: 329.93 | C29: 320.94 | D29: 327.64 | E29: 259.87 | F29: 221.29 | G29: 155.55 | H29: 106.82
A30: Other Current Assets - Total | B30: 26.93 | C30: 46.65 | D30: 79.96 | E30: 32.55 | F30: 12.27
A31: Other Current Assets | B31: 26.93 | C31: 46.65 | D31: 79.96 | E31: 32.55 | F31: 12.27
A32: Total Current Assets | B32: 3980.3 | C32: 4060.58 | D32: 3159.45 | E32: 2614.85 | F32: 2124.38 | G32: 1807.94 | H32: 1429.28
A33: Non-Current Assets
A34: Property, Plant & Equipment - Net - Total | B34: 3196.87 | C34: 2811.42 | D34: 2239.03 | E34: 1731.25 | F34: 1480.52 | G34: 1361.36 | H34: 567.24
A35: Property, Plant & Equipment - excluding Assets Leased Out - Net - Total | B35: 3196.87 | C35: 2811.42 | D35: 2239.03 | E35: 1731.25 | F35: 1480.52 | G35: 1361.36 | H35: 567.24
A36: Property, Plant & Equipment - Gross - Total | B36: 4657.92 | C36: 4028.85 | D36: 3226.33 | E36: 2560.39 | F36: 2171.11 | G36: 1883.03 | H36: 972.48
A37: Property, Plant & Equipment - excluding Assets Leased Out - Gross | B37: 4657.92 | C37: 4028.85 | D37: 3226.33 | E37: 2560.39 | F37: 2171.11 | G37: 1883.03 | H37: 972.48
A38: Land & Buildings - Gross | B38: 1329.36 | C38: 1115.46 | D38: 927.61 | E38: 781.94 | F38: 688.44 | G38: 591.22 | H38: 479.24
A39: Land/Improvements - Gross | B39: 74.46 | C39: 79.5 | D39: 80.69 | E39: 74.3 | F39: 74.26 | G39: 71.83 | H39: 78.64
A40: Buildings - Gross | B40: 27.66 | C40: 29.03 | D40: 28.85 | E40: 30.88 | F40: 30.87 | G40: 30.19 | H40: 38.03
A41: Leasehold Improvements - Gross | B41: 1227.25 | C41: 1006.93 | D41: 818.07 | E41: 676.76 | F41: 583.3 | G41: 489.2 | H41: 362.57
...

Sheet Cash Flow
A1: Company Fundamentals - Cash Flow
A2: Company Name | B2: Lululemon Athletica Inc (LULU.O)
A3: Country of Exchange | B3: United States of America
A4: Country of Headquarters | B4: Canada
A5: TRBC Industry Group | B5: Textiles & Apparel
A6: CF Template | B6: IND
A7: Consolidation Basis | B7: Consolidated
A8: Scaling | B8: Millions
A9: Period | B9: Annual
A10: Export Date | B10: 45922.395
A11: Statement Data | B11: 2025 | C11: 2024 | D11: 2023 | E11: 2022 | F11: 2021 | G11: 2020 | H11: 2019
A12: Period End Date | B12: 45690 | C12: 45319 | D12: 44955 | E12: 44591 | F12: 44227 | G12: 43863 | H12: 43499
A13: Statement Date | B13: 45690 | C13: 45319 | D13: 44955 | E13: 44591 | F13: 44227 | G13: 43863 | H13: 43499
A14: Standardized Currency | B14: USD | C14: USD | D14: USD | E14: USD | F14: USD | G14: USD | H14: USD
A15: Template Type | B15: Industrial - Indirect | C15: Industrial - Indirect | D15: Industrial - Indirect | E15: Industrial - Indirect | F15: Industrial - Indirect | G15: Industrial - Indirect | H15: Industrial - Indirect
A17: Cash Flow - Standardized (Currency: Standardized)
A18: Field Name | B18: 02-02-2025 | C18: 28-01-2024 | D18: 29-01-2023 | E18: 30-01-2022 | F18: 31-01-2021 | G18: 02-02-2020 | H18: 03-02-2019
A19: Operating Cash Flow - Indirect
A20: Profit/(Loss) - Starting Line - Cash Flow | B20: 1814.62 | C20: 1550.19 | D20: 854.8 | E20: 975.32 | F20: 588.91 | G20: 645.6 | H20: 483.8
A21: Non-cash Items & Reconciliation Adjustments - Cash Flow | B21: 509.99 | C21: 546.75 | D21: 708.66 | E21: 284.65 | F21: 261.97 | G21: 217.79 | H21: 146.1
A22: Other Non-Cash Items & Reconciliation Adjustments - Cash Flow - to Reconcile | B22: -36.23 | C22: -4.84 | D22: -23.34 | E22: -18.7 | F22: -13.7 | G22: -11.94 | H22: -6.86
A23: Depreciation, Depletion & Amortization including Impairment - Cash Flow - to Reconcile | B23: 446.52 | C23: 453.89 | D23: 699.7 | E23: 224.21 | F23: 185.48 | G23: 161.93 | H23: 122.48
A24: Depreciation & Depletion - Property, Plant & Equipment - Cash Flow - to Reconcile | B24: 446.52 | C24: 379.38 | D24: 291.79 | E24: 224.21 | F24: 185.48 | G24: 161.93 | H24: 122.48
A25: Impairment - Property, Plant & Equipment including Intangible Assets - Cash Flow - to Reconcile | C25: 74.5 | D25: 407.91
A26: Deferred Income Taxes & Income Tax Credits - Cash Flow - to Reconcile | B26: 57.45 | C26: -28.38 | D26: 3.04 | E26: -5.18 | F26: 34.91 | G26: 24.13 | H26: 16.79
A27: Assets Sale - Gain/(Loss) - Cash Flow - to Reconcile | D27: -10.18
A28: Financial Assets - Unrealized Gain/(Loss) - Cash Flow - to Reconcile | B28: -47.76 | C28: 32.53 | D28: -38.65 | E28: 15.19 | F28: 4.49 | G28: -1.92 | H28: -14.88
A29: Share Based Payments - Cash Flow - to Reconcile | B29: 90.01 | C29: 93.56 | D29: 78.08 | E29: 69.14 | F29: 50.8 | G29: 45.59 | H29: 28.57
A30: Cash Flow from Operating Activities before Changes in Working Capital | B30: 2324.61 | C30: 2096.94 | D30: 1563.46 | E30: 1259.98 | F30: 850.89 | G30: 863.39 | H30: 629.9
A31: Working Capital - Increase/(Decrease) - Cash Flow | B31: -51.89 | C31: 199.22 | D31: -596.99 | E31: 129.13 | F31: -47.55 | G31: -194.07 | H31: 112.88
A32: Accounts Receivables - Decrease/(Increase) - Cash Flow | B32: 1.63
A33: Inventories - Decrease/(Increase) - Cash Flow | B33: -156.08 | C33: 66.58 | D33: -510.51 | E33: -323.61 | F33: -96.55 | G33: -117.59 | H33: -85.94
A34: Prepaid Expenses - Decrease/(Increase) - Cash Flow | B34: -73.82 | C34: 49.08 | D34: -180.53 | E34: -62.3 | F34: -124.96 | G34: -117.38 | H34: -31.09
A35: Other Assets - Decrease/(Increase) - Cash Flow | B35: -73.2 | C35: -53.28 | D35: -36.52 | E35: -17.56 | F35: -49.06
A36: Accounts Payable - Increase/(Decrease) - Cash Flow | B36: -57.04 | C36: 177.37 | D36: -107.28 | E36: 117.66 | F36: 82.66 | G36: -14.81 | H36: 71.96
A37: Accrued Expenses - Increase/(Decrease) - Cash Flow | B37: 81.03 | C37: -1.41 | D37: 112.62 | E37: 179.15 | F37: 92.47 | G37: 15.73 | H37: 45.91
A38: Taxes Payable - Increase/(Decrease) - Cash Flow | B38: 157.21 | C38: -173.2 | D38: 35.99 | E38: 120.78 | F38: -24.12 | G38: -34.14 | H38: 46.43
A39: Other Liabilities - Increase/(Decrease) -Total - Cash Flow | B39: 44.9 | C39: 96.55 | D39: 65.34 | E39: 101.51 | F39: 58.75 | G39: 56.7 | H39: 65.61
A40: Other Assets & Liabilities - Increase/(Decrease) - Net - Cash Flow | B40: 23.5 | C40: 37.53 | D40: 23.91 | E40: 13.49 | F40: 13.27 | G40: 17.42
A41: Net Cash Flow from Operating Activities | B41: 2272.71 | C41: 2296.16 | D41: 966.46 | E41: 1389.11 | F41: 803.34 | G41: 669.32 | H41: 742.78
...

Sheet Pension
A1: Company Fundamentals - Pension
A2: Company Name | B2: Lululemon Athletica Inc (LULU.O)
A3: Country of Exchange | B3: United States of America
A4: Country of Headquarters | B4: Canada
A5: TRBC Industry Group | B5: Textiles & Apparel
A6: CF Template | B6: IND
A7: Consolidation Basis | B7: Consolidated
A8: Scaling | B8: Millions
A9: Period | B9: Annual
A10: Export Date | B10: 45922.395
A11: Statement Data | B11: 2025 | C11: 2024 | D11: 2023 | E11: 2022 | F11: 2021 | G11: 2020 | H11: 2019
A12: Period End Date | B12: 45690 | C12: 45319 | D12: 44955 | E12: 44591 | F12: 44227 | G12: 43863 | H12: 43499
A13: Statement Date | B13: 45690 | C13: 45319 | D13: 44955 | E13: 44591 | F13: 44227 | G13: 43863 | H13: 43499
A14: Standardized Currency | B14: USD | C14: USD | D14: USD | E14: USD | F14: USD | G14: USD | H14: USD
A15: Template Type | B15: Industrial | C15: Industrial | D15: Industrial | E15: Industrial | F15: Industrial | G15: Industrial | H15: Industrial
A17: Pension - Standardized (Currency: Standardized)
A18: Field Name | B18: 02-02-2025 | C18: 28-01-2024 | D18: 29-01-2023 | E18: 30-01-2022 | F18: 31-01-2021 | G18: 02-02-2020 | H18: 03-02-2019
A19: Income/Expense
A20: Total Pension Plans - Total Pension & Post-Retirement | B20: 22.2 | C20: 19.8 | D20: 14 | E20: 11.8 | F20: 9.2 | G20: 8.5 | H20: 6.4
A21: Total Pension Plan Expense - Total | B21: 22.2 | C21: 19.8 | D21: 14 | E21: 11.8 | F21: 9.2 | G21: 8.5 | H21: 6.4
A22: Total Pension Plans - Domestic | B22: 22.2 | C22: 19.8 | D22: 14 | E22: 11.8 | F22: 9.2 | G22: 8.5 | H22: 6.4
A23: Defined Contribution Expense - Total Pension & Post-Retirement | B23: 22.2 | C23: 19.8 | D23: 14 | E23: 11.8 | F23: 9.2 | G23: 8.5 | H23: 6.4
A24: Defined Contribution Expense - Total Pension | B24: 22.2 | C24: 19.8 | D24: 14 | E24: 11.8 | F24: 9.2 | G24: 8.5 | H24: 6.4
A25: Defined Contribution Expense - Domestic | B25: 22.2 | C25: 19.8 | D25: 14 | E25: 11.8 | F25: 9.2 | G25: 8.5 | H25: 6.4

Sheet Financial Summary
A1: Company Fundamentals - Financial Summary
A2: Company Name | B2: Lululemon Athletica Inc (LULU.O)
A3: Country of Exchange | B3: United States of America
A4: Country of Headquarters | B4: Canada
A5: TRBC Industry Group | B5: Textiles & Apparel
A6: CF Template | B6: IND
A7: Consolidation Basis | B7: Consolidated
A8: Scaling | B8: Millions
A9: Period | B9: Annual
A10: Export Date | B10: 45922.395
A11: Statement Data | B11: 2025 | C11: 2024 | D11: 2023 | E11: 2022 | F11: 2021 | G11: 2020 | H11: 2019
A12: Period End Date | B12: 45690 | C12: 45319 | D12: 44955 | E12: 44591 | F12: 44227 | G12: 43863 | H12: 43499
A13: Statement Date | B13: 45690 | C13: 45319 | D13: 44955 | E13: 44591 | F13: 44227 | G13: 43863 | H13: 43499
A14: Standardized Currency | B14: USD | C14: USD | D14: USD | E14: USD | F14: USD | G14: USD | H14: USD
A15: Template Type | B15: Industrial - Gross Profit | C15: Industrial - Gross Profit | D15: Industrial - Gross Profit | E15: Industrial - Gross Profit | F15: Industrial - Gross Profit | G15: Industrial - Gross Profit | H15: Industrial - Gross Profit
A17: Financial Summary - Standardized (Currency: Standardized)
A18: Field Name | B18: 02-02-2025 | C18: 28-01-2024 | D18: 29-01-2023 | E18: 30-01-2022 | F18: 31-01-2021 | G18: 02-02-2020 | H18: 03-02-2019
A19: Selected Income Statement Items
A20: Revenue from Business Activities - Total | B20: 10588.13 | C20: 9619.28 | D20: 8110.52 | E20: 6256.62 | F20: 4401.88 | G20: 3979.3 | H20: 3288.32
A21: Gross Profit - Industrials/Property - Total | B21: 6268.08 | C21: 5604.4 | D21: 4483.59 | E21: 3599.78 | F21: 2458.83 | G21: 2223.39 | H21: 1816.29
A22: Operating Profit before Non-Recurring Income/Expense | B22: 2509.2 | C22: 2207.18 | D22: 1726.14 | E22: 1374.75 | F22: 849.83 | G22: 890.62 | H22: 704.44
A23: Earnings before Interest, Taxes, Depreciation & Amortization (EBITDA) | B23: 2955.72 | C23: 2586.56 | D23: 2017.93 | E23: 1598.96 | F23: 1035.31 | G23: 1052.55 | H23: 826.93
A24: Income before Discontinued Operations & Extraordinary Items | B24: 1814.62 | C24: 1550.19 | D24: 854.8 | E24: 975.32 | F24: 588.91 | G24: 645.6 | H24: 491.27
A25: Selected Balance Sheet Items
A26: Cash & Cash Equivalents | B26: 1984.34 | C26: 2243.97 | D26: 1154.87 | E26: 1259.87 | F26: 1150.52 | G26: 1093.51 | H26: 881.32
A27: Cash & Short-Term Investments | B27: 1984.34 | C27: 2243.97 | D27: 1154.87 | E27: 1259.87 | F27: 1150.52 | G27: 1093.51 | H27: 881.32
A28: Total Assets | B28: 7603.29 | C28: 7091.94 | D28: 5607.04 | E28: 4942.48 | F28: 4185.22 | G28: 3281.35 | H28: 2084.71
A29: Debt - Total | B29: 12.4 | C29: 10.8 | D29: 8.6 | E29: 4
A30: Common Equity - Total | B30: 4324.05 | C30: 4232.08 | D30: 3148.8 | E30: 2740.05 | F30: 2558.57 | G30: 1952.22 | H30: 1445.98
A31: Selected Cash Flow Items
A32: Net Cash Flow from Operating Activities | B32: 2272.71 | C32: 2296.16 | D32: 966.46 | E32: 1389.11 | F32: 803.34 | G32: 669.32 | H32: 742.78
A33: Depreciation, Depletion & Amortization including Impairment - Cash Flow - to Reconcile | B33: 446.52 | C33: 453.89 | D33: 699.7 | E33: 224.21 | F33: 185.48 | G33: 161.93 | H33: 122.48
A34: Capital Expenditures - Net - Cash Flow | B34: 689.23 | C34: 651.87 | D34: 638.66 | E34: 394.5 | F34: 229.23 | G34: 283.05 | H34: 225.81
A35: Net Change in Cash - Total | B35: -259.63 | C35: 1089.1 | D35: -105 | E35: 109.35 | F35: 57.01 | G35: 212.19 | H35: -109.18
A36: Free Cash Flow Net of Dividends | B36: 1583.48 | C36: 1644.3 | D36: 327.81 | E36: 994.61 | F36: 574.11 | G36: 386.27 | H36: 516.97
A37: Selected Per Share Data
A38: Dividend Yield - Common Stock - Gross - Issue Specific - %
A39: Dividend Yield - Common Stock - Net - Issue Specific - %
A40: EPS - Diluted - excluding Extraordinary Items Applicable to Common - Total | B40: 14.64 | C40: 12.2 | D40: 6.68 | E40: 7.49 | F40: 4.5 | G40: 4.93 | H40: 3.67
A41: Shares used to calculate Diluted EPS - Total | B41: 123.94 | C41: 127.06 | D41: 128.02 | E41: 130.29 | F41: 130.87 | G41: 130.96 | H41: 133.97
...

Sheet Valuation
A1: Company Fundamentals - Valuation
A2: Company Name | B2: Lululemon Athletica Inc (LULU.O)
A3: Country of Exchange | B3: United States of America
A4: Country of Headquarters | B4: Canada
A5: TRBC Industry Group | B5: Textiles & Apparel
A6: CF Template | B6: IND
A7: Consolidation Basis | B7: Consolidated
A8: Scaling | B8: Millions
A9: Period | B9: Annual
A10: Export Date | B10: 45922.395
A11: Statement Data | B11: 2025 | C11: 2024 | D11: 2023 | E11: 2022 | F11: 2021 | G11: 2020 | H11: 2019
A12: Period End Date | B12: 45690 | C12: 45319 | D12: 44955 | E12: 44591 | F12: 44227 | G12: 43863 | H12: 43499
A13: Statement Date | B13: 45690 | C13: 45319 | D13: 44955 | E13: 44591 | F13: 44227 | G13: 43863 | H13: 43499
A14: Standardized Currency | B14: USD | C14: USD | D14: USD | E14: USD | F14: USD | G14: USD | H14: USD
A15: Template Type | B15: Industrial - Gross Profit | C15: Industrial - Gross Profit | D15: Industrial - Gross Profit | E15: Industrial - Gross Profit | F15: Industrial - Gross Profit | G15: Industrial - Gross Profit | H15: Industrial - Gross Profit
A17: Valuation - Standardized (Currency: Standardized)
A18: Field Name | B18: 02-02-2025 | C18: 28-01-2024 | D18: 29-01-2023 | E18: 30-01-2022 | F18: 31-01-2021 | G18: 02-02-2020 | H18: 03-02-2019
A19: Enterprise Value
A20: Enterprise Value | B20: 48470.8 | C20: 58089.79 | D20: 38518.75 | E20: 39589.37 | F20: 41688.99 | G20: 30097.79 | H20: 18465.55
A21: Enterprise Value, 5 Year Average | B21: 45271.54 | C21: 41596.94 | D21: 33672.09 | E21: 27911.41 | F21: 21678.51 | G21: 14960.42 | H21: 10689.08
A22: Market Capitalization
A23: Market Capitalization | B23: 50442.74 | C23: 60322.96 | D23: 39665.02 | E23: 40845.24 | F23: 42839.51 | G23: 31191.3 | H23: 19346.87
A24: Market Capitalization, 5 Year Average | B24: 46823.09 | C24: 42972.81 | D24: 34777.59 | E24: 28985.75 | F24: 22648.64 | G24: 15800.75 | H24: 11443.6
A25: Price Close
A26: Price Close (End of Period) | B26: 414.2 | C26: 478.03 | D26: 310.85 | E26: 315.91 | F26: 328.68 | G26: 239.39 | H26: 146.12
A27: Price Close (End of Period), 5 Year Average | B27: 369.53 | C27: 334.57 | D27: 268.19 | E27: 221.84 | F27: 172.02 | G27: 118.7 | H27: 84.07
A28: FOCF Yield
A29: Free Cash Flow Yield - % | B29: 3.08 | C29: 2.71 | D29: 0.82 | E29: 2.42 | F29: 1.33 | G29: 1.23 | H29: 2.64
A30: Free Cash Flow Yield - %, 5 Year Average | B30: 2.18 | C30: 1.82 | D30: 1.6 | E30: 1.92 | F30: 1.79 | G30: 2.03 | H30: 2.49
A31: Dividend Yield
A32: Dividend Yield - Common Stock - Net - Issue Specific - % | B32: 0 | C32: 0 | D32: 0 | E32: 0 | F32: 0 | G32: 0 | H32: 0
A33: Dividend Yield - Common Stock - Net - Issue Specific - %, 5 Year Average | B33: 0 | C33: 0 | D33: 0 | E33: 0 | F33: 0 | G33: 0 | H33: 0
A34: Dividend Yield - Common Stock - Gross - Issue Specific - % | B34: 0 | C34: 0 | D34: 0 | E34: 0 | F34: 0 | G34: 0 | H34: 0
A35: Dividend Yield - Common Stock - Gross - Issue Specific - %, 5 Year Average | B35: 0 | C35: 0 | D35: 0 | E35: 0 | F35: 0 | G35: 0 | H35: 0
A36: Price to Book
A37: Price to Book Value per Share - Issue Specific | B37: 12.11 | C37: 14.84 | D37: 13.07 | E37: 15.42 | F37: 17.41 | G37: 16.75 | H37: 14.17
A38: Price to Book Value per Share - Issue Specific, 5 Year Average | B38: 14.26 | C38: 15.25 | D38: 15.28 | E38: 14.8 | F38: 13.49 | G38: 11.45 | H38: 9.29
A39: Price to Tangible Book
A40: Price to Tangible Book Value per Share | B40: 12.61 | C40: 14.92 | D40: 13.27 | E40: 18.51 | F40: 21.3 | G40: 16.96 | H40: 14.42
A41: Price to Tangible Book Value per Share, 5 Year Average | B41: 15.29 | C41: 16.39 | D41: 16.73 | E41: 16.41 | F41: 14.43 | G41: 11.64 | H41: 9.47
...

Sheet VALUATION CALC
A1: Firm Valuation | I1: Sites Used
B2: Latest P/E ratio | D2: ADDITIONAL: Latest P/B Ratio | F2: Latest enterprice Value/EBITDA | I2: 1 | J2: https://stockanalysis.com/quote/tyo/7936/statistics/
A3: ASICS | C3: 31.5 | E3: 9.77 | G3: 16.45 | I3: 2 | J3: https://stockanalysis.com/stocks/nke/statistics/
C4: + | E4: + | G4: + | I4: 3 | J4: https://stockanalysis.com/quote/etr/ADS/statistics/
A5: ADIDAS | C5: 22.36 | E5: 4.45 | G5: 10.37
C6: + | E6: + | G6: +
A7: NIKE | C7: 32.24 | E7: 6.89 | G7: 22.71
A9: Competitors Average | C9: =AVERAGE(C3,C5,C7) -> 28.7 | E9: =AVERAGE(E3,E5,E7) -> 7.0366667 | G9: =AVERAGE(G3,G5,G7) -> 16.51
A11: Expected Stock Price | B11: P/E Multiple = | C11: =C39 -> 420.168 | D11: P/B Multiple= | E11: 240.7 | F11: EBITDA Multiple= | G11: =J64 -> 401.66833
A13: NOTE: | B13: Even though the companies report in different currencies, we didn’t need to convert anything because P/E, P/B, and EV/EBITDA are ratio-based. These multiples are naturally currency-neutral
I14: SUMMARY
I15: Company | J15: Current P/E ratio
I16: Lululemon | J16: =D33 -> 28.29235
I17: ASICS | J17: =C3 -> 31.5
I18: ADIDAS | J18: =C5 -> 22.36
I19: NIKE | J19: =C7 -> 32.24
I24: SUMMARY
I25: Company | J25: Current P/B ratio
I26: Lululemon | J26: =D51 -> 12.11
I27: ASICS | J27: =E3 -> 9.77
A28: Price to Earnings Ratio (Lululemon) | I28: ADIDAS | J28: =E5 -> 4.45
A29: Year | B29: Price | C29: Earnings per Share | D29: P/E Ratio | I29: NIKE | J29: =E7 -> 6.89
A30: 2022 | B30: =Valuation!E26 -> 315.91 | C30: =Valuation!E55 -> 40.48 | D30: =B30/C30 -> 7.8041008
A31: 2023 | B31: =Valuation!D26 -> 310.85 | C31: =Valuation!D55 -> 31.51 | D31: =B31/C31 -> 9.8651222
A32: 2024 | B32: =Valuation!C26 -> 478.03 | C32: =Valuation!C55 -> 37.38 | D32: =B32/C32 -> 12.78839
A33: 2025 / Current | B33: =Valuation!B26 -> 414.2 | C33: 14.64 | D33: =B33/C33 -> 28.29235 | E33: ⟵ | F33: =B33/C33'
B34: ↑ | C34: ↑
B35: =Valuation!B26' | C35: ='Financial Summary'!B63'
A37: PE multiple | I37: Method used | J37: Expected Stock Price
A38: Current EPS | B38: Industry Average | C38: Estimated Stock Price
A39: =C33 -> 14.64 | B39: =C9 -> 28.7 | C39: =A39 * B39 -> 420.168 | I39: P/E multiple | J39: =C11 -> 420.168
C40: ↑ | I40: P/B multiple | J40: =E11 -> 240.7
C41: =A37 * B37' | I41: EBITDA multiple | J41: =G11 -> 401.66833
A46: Price to Book Ratio (Lululemon)
A47: Year | B47: Market Price per Share (USD) | C47: Book Value per Share (USD) | D47: P/B Ratio
A48: 2022 | B48: 315.91 | C48: =B48/D48 -> 20.48703 | D48: =Valuation!E37 -> 15.42
A49: 2023 | B49: 310.85 | C49: =B49/D49 -> 23.783474 | D49: =Valuation!D37 -> 13.07
A50: 2024 | B50: 478.03 | C50: =B50/D50 -> 32.212264 | D50: =Valuation!C37 -> 14.84
A51: 2025 / Current | B51: 414.2 | C51: =B51/D51 -> 34.203138 | D51: =Valuation!B37 -> 12.11 | E51: ⟵ | F51: =Valuation!B37'
A53: P/B Multiple
...

Sheet DCF

Sheet MULTIPLES

Sheet Operating Metrics
A1: Company Fundamentals - Operating Metrics
A2: Company Name | B2: Lululemon Athletica Inc (LULU.O)
A3: Country of Exchange | B3: United States of America
A4: Country of Headquarters | B4: Canada
A5: TRBC Industry Group | B5: Textiles & Apparel
A6: CF Template | B6: IND
A7: Consolidation Basis | B7: Consolidated
A8: Scaling | B8: Millions
A9: Period | B9: Annual
A10: Measure system | B10: Metric
A11: Statement Data | B11: 2025 | C11: 2024 | D11: 2023 | E11: 2022 | F11: 2021 | G11: 2020 | H11: 2019
A12: Period End Date | B12: 45690 | C12: 45319 | D12: 44955 | E12: 44591 | F12: 44227 | G12: 43863 | H12: 43499
A13: Statement Date | B13: 45690 | C13: 45319 | D13: 44955 | E13: 44591 | F13: 44227 | G13: 43863 | H13: 43499
A14: Standardized Currency | B14: USD | C14: USD | D14: USD | E14: USD | F14: USD | G14: USD | H14: USD
A15: Template Type | B15: Industrial | C15: Industrial | D15: Industrial | E15: Industrial | F15: Industrial | G15: Industrial | H15: Industrial
A17: Operating Metrics - Standardized (Currency: Standardized)
A18: Field Name | B18: 02-02-2025 | C18: 28-01-2024 | D18: 29-01-2023 | E18: 30-01-2022 | F18: 31-01-2021 | G18: 02-02-2020 | H18: 03-02-2019
A19: Other Retail Measures
A20: Sales per Unit - Average - Total | H20: 146.69
A21: Comparable Store Sales (Growth %)
A22: Comparable Store Sales Growth Rate - Retail - Total - % | B22: 4 | C22: 8 | D22: 19 | G22: 9 | H22: 7
A23: Comparable Store Sales - Total - Retail | H23: 105452000
A24: Other Retail Measures
A25: Merchandise Margins - Total - % | B25: 59.2 | C25: 58.3 | D25: 55.4 | E25: 57.7 | F25: 56 | G25: 55.9 | H25: 55.2
A26: Stores Number
A27: Stores Closed - Number - Total | B27: 9 | C27: 7 | D27: 6 | E27: 3 | F27: 10 | G27: 6 | H27: 3
A28: Stores Opened - Number - Total | B28: 56 | C28: 56 | D28: 87 | E28: 56 | F28: 40 | G28: 57 | H28: 39
A29: Stores - End of Period - Number - Total | B29: 767 | C29: 711 | D29: 655 | E29: 574 | F29: 521 | G29: 491 | H29: 440
A30: Revenues
A31: Online Sales - Total | B31: 4570446000 | C31: 4311110000 | D31: 3699791000 | E31: 2777944000 | F31: 2284068000 | G31: 1137822000 | H31: 858856000
A32: Retail Sales - Total | B32: 5007872000 | C32: 4410956000 | D32: 3648127000 | E32: 2821497000 | F32: 1658807000 | G32: 2501067000 | H32: 2126363000
A33: Selling Space
A34: Selling Space - Gross - Total | B34: 313269.05 | C34: 275643.32 | D34: 239225.33 | E34: 197418.96 | F34: 172613.85 | G34: 156077.11 | H34: 132479.74
